Workbook

Sheet GWIND_BS
A1: GALATA WIND ENERJİ A.Ş. — KONSOLİDE BİLANÇO / CONSOLIDATED BALANCE SHEET (BİN TL) | L1: DİKEY ANALİZ (% Toplam Aktifler)
A2: KALEM (BİN TL) | B2: 31.12.2025 (2025 SAG) | C2: 31.12.2024 (2025 SAG) | D2: 31.12.2024 (2024 SAG) | E2: 31.12.2023 (2024 SAG) | F2: 31.12.2023 (2023 SAG) | G2: 31.12.2022 (2023 SAG) | H2: 31.12.2022 (Nominal) | I2: 31.12.2021 (Nominal) | J2: 31.12.2020 (Nominal) | L2: 31.12.2025 (2025 SAG) | M2: 31.12.2024 (2025 SAG) | N2: 31.12.2024 (2024 SAG) | O2: 31.12.2023 (2024 SAG) | P2: 31.12.2023 (2023 SAG) | Q2: 31.12.2022 (2023 SAG) | R2: 31.12.2022 (Nominal) | S2: 31.12.2021 (Nominal) | T2: 31.12.2020 (Nominal)
A3: VARLIKLAR / ASSETS
A4: DÖNEN VARLIKLAR / CURRENT ASSETS
A5: Nakit ve Nakit Benzerleri (Cash & equivalents) | B5: 1187134.7 | C5: 1725691.1 | D5: 1318405.1 | E5: 95293.91 | F5: 66002.716 | G5: 1085983.8 | H5: 659079.07 | I5: 158919.08 | J5: 66124.675 | L5: =IFERROR(B5/B16,"") -> 0.05836851 | M5: =IFERROR(C5/C16,"") -> 0.089024187 | N5: =IFERROR(D5/D16,"") -> 0.089024187 | O5: =IFERROR(E5/E16,"") -> 0.0072058993 | P5: =IFERROR(F5/F16,"") -> 0.0072058993 | Q5: =IFERROR(G5/G16,"") -> 0.12394282 | R5: =IFERROR(H5/H16,"") -> 0.26722762 | S5: =IFERROR(I5/I16,"") -> 0.089907404 | T5: =IFERROR(J5/J16,"") -> 0.040802119
A6: Finansal Yatırımlar KV (ST financial investments) | B6: 653770.19 | C6: 0 | D6: 0 | E6: 127473.44 | F6: 88290.984 | G6: 125720.82 | H6: 76299.442 | I6: 0 | J6: 0 | L6: =IFERROR(B6/B16,"") -> 0.032144282 | M6: =IFERROR(C6/C16,"") -> 0 | N6: =IFERROR(D6/D16,"") -> 0 | O6: =IFERROR(E6/E16,"") -> 0.0096392388 | P6: =IFERROR(F6/F16,"") -> 0.0096392388 | Q6: =IFERROR(G6/G16,"") -> 0.014348458 | R6: =IFERROR(H6/H16,"") -> 0.030936073 | S6: =IFERROR(I6/I16,"") -> 0 | T6: =IFERROR(J6/J16,"") -> 0
A7: Ticari Alacaklar (Trade receivables, net) | B7: 284414.93 | C7: 287927.65 | D7: 219977.91 | E7: 199688.28 | F7: 138308.61 | G7: 138620.85 | H7: 84128.414 | I7: 84322.217 | J7: 34809.442 | L7: =IFERROR(B7/B16,"") -> 0.013983987 | M7: =IFERROR(C7/C16,"") -> 0.014853484 | N7: =IFERROR(D7/D16,"") -> 0.014853822 | O7: =IFERROR(E7/E16,"") -> 0.015099953 | P7: =IFERROR(F7/F16,"") -> 0.015099954 | Q7: =IFERROR(G7/G16,"") -> 0.015820732 | R7: =IFERROR(H7/H16,"") -> 0.034110377 | S7: =IFERROR(I7/I16,"") -> 0.04770473 | T7: =IFERROR(J7/J16,"") -> 0.021479108
A8: Stoklar (Inventories) | B8: 4409.483 | C8: 9281.389 | D8: 7090.857 | E8: 7090.857 | F8: 4911.288 | G8: 4939.75 | H8: 818.695 | I8: 835.022 | J8: 1664.977 | L8: =IFERROR(B8/B16,"") -> 0.0002168035 | M8: =IFERROR(C8/C16,"") -> 0.00047880416 | N8: =IFERROR(D8/D16,"") -> 0.0004788041 | O8: =IFERROR(E8/E16,"") -> 0.00053619377 | P8: =IFERROR(F8/F16,"") -> 0.00053619379 | Q8: =IFERROR(G8/G16,"") -> 0.00056377135 | R8: =IFERROR(H8/H16,"") -> 0.00033194487 | S8: =IFERROR(I8/I16,"") -> 0.00047240811 | T8: =IFERROR(J8/J16,"") -> 0.0010273713
A9: Diğer Dönen Varlıklar (Peşin öd., diğer alacaklar, vb.) | B9: 60201.531 | C9: 94202.658 | D9: 71964.575 | E9: 41725 | F9: 28899.679 | G9: 150499.57 | H9: 87980.426 | I9: 145014.46 | J9: 68896.001 | L9: =IFERROR(B9/B16,"") -> 0.0029599621 | M9: =IFERROR(C9/C16,"") -> 0.0048596848 | N9: =IFERROR(D9/D16,"") -> 0.0048593469 | O9: =IFERROR(E9/E16,"") -> 0.0031551455 | P9: =IFERROR(F9/F16,"") -> 0.0031551456 | Q9: =IFERROR(G9/G16,"") -> 0.017176446 | R9: =IFERROR(H9/H16,"") -> 0.035672199 | S9: =IFERROR(I9/I16,"") -> 0.08204096 | T9: =IFERROR(J9/J16,"") -> 0.042512161
A10: DÖNEN VARLIKLAR TOPLAM (TOTAL CURRENT ASSETS) | B10: =SUM(B5:B9) -> 2189930.8 | C10: =SUM(C5:C9) -> 2117102.8 | D10: =SUM(D5:D9) -> 1617438.5 | E10: =SUM(E5:E9) -> 471271.48 | F10: =SUM(F5:F9) -> 326413.28 | G10: =SUM(G5:G9) -> 1505764.8 | H10: =SUM(H5:H9) -> 908306.05 | I10: =SUM(I5:I9) -> 389090.77 | J10: =SUM(J5:J9) -> 171495.1 | L10: =IFERROR(B10/B16,"") -> 0.10767354 | M10: =IFERROR(C10/C16,"") -> 0.10921616 | N10: =IFERROR(D10/D16,"") -> 0.10921616 | O10: =IFERROR(E10/E16,"") -> 0.035636431 | P10: =IFERROR(F10/F16,"") -> 0.035636431 | Q10: =IFERROR(G10/G16,"") -> 0.17185223 | R10: =IFERROR(H10/H16,"") -> 0.36827821 | S10: =IFERROR(I10/I16,"") -> 0.2201255 | T10: =IFERROR(J10/J16,"") -> 0.10582076
A11: DURAN VARLIKLAR / NON-CURRENT ASSETS
A12: Maddi Duran Varlıklar (Property, plant & equipment) | B12: 11487462 | C12: 11669954 | D12: 8915690.1 | E12: 7429653.2 | F12: 5145945.7 | G12: 4148764.7 | H12: 892677.41 | I12: 880684.72 | J12: 849662 | L12: =IFERROR(B12/B16,"") -> 0.56481041 | M12: =IFERROR(C12/C16,"") -> 0.60202441 | N12: =IFERROR(D12/D16,"") -> 0.60202441 | O12: =IFERROR(E12/E16,"") -> 0.56181274 | P12: =IFERROR(F12/F16,"") -> 0.56181274 | Q12: =IFERROR(G12/G16,"") -> 0.47349657 | R12: =IFERROR(H12/H16,"") -> 0.36194148 | S12: =IFERROR(I12/I16,"") -> 0.49824149 | T12: =IFERROR(J12/J16,"") -> 0.5242825
A13: Maddi Olmayan Duran Varlıklar (Lis., Şerefiye, Haklar) | B13: 6097478.8 | C13: 5025353.2 | D13: 3839303.1 | E13: 3829789.9 | F13: 2652598.3 | G13: 2718735.1 | H13: 341391.08 | I13: 312943.83 | J13: 319686.11 | L13: =IFERROR(B13/B16,"") -> 0.29979812 | M13: =IFERROR(C13/C16,"") -> 0.25924568 | N13: =IFERROR(D13/D16,"") -> 0.25924568 | O13: =IFERROR(E13/E16,"") -> 0.28959962 | P13: =IFERROR(F13/F16,"") -> 0.28959955 | Q13: =IFERROR(G13/G16,"") -> 0.31028796 | R13: =IFERROR(H13/H16,"") -> 0.13841909 | S13: =IFERROR(I13/I16,"") -> 0.17704588 | T13: =IFERROR(J13/J16,"") -> 0.19726178
A14: Diğer Duran Varlıklar (Türev, KHV, Peşin Öd., ETVarlık) | B14: 563744.18 | C14: 572109.77 | D14: 437084.26 | E14: 1493715.4 | F14: 1034581.7 | G14: 388709.53 | H14: 323983.84 | I14: 184866.76 | J14: 279775.44 | L14: =IFERROR(B14/B16,"") -> 0.027717923 | M14: =IFERROR(C14/C16,"") -> 0.029513744 | N14: =IFERROR(D14/D16,"") -> 0.029513744 | O14: =IFERROR(E14/E16,"") -> 0.11295121 | P14: =IFERROR(F14/F16,"") -> 0.11295128 | Q14: =IFERROR(G14/G16,"") -> 0.044363237 | R14: =IFERROR(H14/H16,"") -> 0.13136122 | S14: =IFERROR(I14/I16,"") -> 0.10458713 | T14: =IFERROR(J14/J16,"") -> 0.17263496
A15: DURAN VARLIKLAR TOPLAM (TOTAL NON-CURRENT ASSETS) | B15: =SUM(B12:B14) -> 18148685 | C15: =SUM(C12:C14) -> 17267417 | D15: =SUM(D12:D14) -> 13192077 | E15: =SUM(E12:E14) -> 12753158 | F15: =SUM(F12:F14) -> 8833125.8 | G15: =SUM(G12:G14) -> 7256209.3 | H15: =SUM(H12:H14) -> 1558052.3 | I15: =SUM(I12:I14) -> 1378495.3 | J15: =SUM(J12:J14) -> 1449123.5 | L15: =IFERROR(B15/B16,"") -> 0.89232646 | M15: =IFERROR(C15/C16,"") -> 0.89078384 | N15: =IFERROR(D15/D16,"") -> 0.89078384 | O15: =IFERROR(E15/E16,"") -> 0.96436357 | P15: =IFERROR(F15/F16,"") -> 0.96436357 | Q15: =IFERROR(G15/G16,"") -> 0.82814777 | R15: =IFERROR(H15/H16,"") -> 0.63172179 | S15: =IFERROR(I15/I16,"") -> 0.7798745 | T15: =IFERROR(J15/J16,"") -> 0.89417924
A16: TOPLAM VARLIKLAR (TOTAL ASSETS) | B16: =B10+B15 -> 20338616 | C16: =C10+C15 -> 19384520 | D16: =D10+D15 -> 14809516 | E16: =E10+E15 -> 13224430 | F16: =F10+F15 -> 9159539.1 | G16: =G10+G15 -> 8761974.1 | H16: =H10+H15 -> 2466358.4 | I16: =I10+I15 -> 1767586.1 | J16: =J10+J15 -> 1620618.6 | L16: =IFERROR(B16/B16,"") -> 1 | M16: =IFERROR(C16/C16,"") -> 1 | N16: =IFERROR(D16/D16,"") -> 1 | O16: =IFERROR(E16/E16,"") -> 1 | P16: =IFERROR(F16/F16,"") -> 1 | Q16: =IFERROR(G16/G16,"") -> 1 | R16: =IFERROR(H16/H16,"") -> 1 | S16: =IFERROR(I16/I16,"") -> 1 | T16: =IFERROR(J16/J16,"") -> 1
A17: KAYNAKLAR / LIABILITIES & EQUITY
A18: KISA VADELİ YÜKÜMLÜLÜKLER / CURRENT LIABILITIES
A19: Kısa Vadeli Finansal Borçlar (ST borrowings + lease ST) | B19: 707962.99 | C19: 735797.55 | D19: 562139.55 | E19: 118107.89 | F19: 118108.89 | G19: 112506.03 | H19: 68279.442 | I19: 249449.8 | J19: 123620.11 | L19: =IFERROR(B19/B16,"") -> 0.034808809 | M19: =IFERROR(C19/C16,"") -> 0.037957996 | N19: =IFERROR(D19/D16,"") -> 0.037957996 | O19: =IFERROR(E19/E16,"") -> 0.0089310385 | P19: =IFERROR(F19/F16,"") -> 0.012894633 | Q19: =IFERROR(G19/G16,"") -> 0.01284026 | R19: =IFERROR(H19/H16,"") -> 0.027684315 | S19: =IFERROR(I19/I16,"") -> 0.14112456 | T19: =IFERROR(J19/J16,"") -> 0.07627958
A20: Ticari Borçlar (Trade payables, related + 3rd party) | B20: 61033.761 | C20: 181188.88 | D20: 138425.9 | E20: 101813.21 | F20: 70335.328 | G20: 45170.596 | H20: 17469.688 | I20: 8873.794 | J20: 7050.392 | L20: =IFERROR(B20/B16,"") -> 0.0030008808 | M20: =IFERROR(C20/C16,"") -> 0.0093470912 | N20: =IFERROR(D20/D16,"") -> 0.0093470912 | O20: =IFERROR(E20/E16,"") -> 0.0076988731 | P20: =IFERROR(F20/F16,"") -> 0.0076789157 | Q20: =IFERROR(G20/G16,"") -> 0.005155299 | R20: =IFERROR(H20/H16,"") -> 0.0070831912 | S20: =IFERROR(I20/I16,"") -> 0.0050202896 | T20: =IFERROR(J20/J16,"") -> 0.0043504325
A21: Diğer KV Yükümlülükler (diğer borçlar, karşılıklar, vb.) | B21: 116612.05 | C21: 139222.61 | D21: 106364.23 | E21: 343970.98 | F21: 202120.18 | G21: 19145.416 | H21: 21563.432 | I21: 29723.446 | J21: 171823.45
A22: KV YÜKÜMLÜLÜKLER TOPLAM (TOTAL CURRENT LIABILITIES) | B22: =SUM(B19:B21) -> 885608.8 | C22: =SUM(C19:C21) -> 1056209 | D22: =SUM(D19:D21) -> 806929.67 | E22: =SUM(E19:E21) -> 563892.08 | F22: =SUM(F19:F21) -> 390564.4 | G22: =SUM(G19:G21) -> 176822.04 | H22: =SUM(H19:H21) -> 107312.56 | I22: =SUM(I19:I21) -> 288047.04 | J22: =SUM(J19:J21) -> 302493.95 | L22: =IFERROR(B22/B16,"") -> 0.043543219 | M22: =IFERROR(C22/C16,"") -> 0.054487242 | N22: =IFERROR(D22/D16,"") -> 0.054487242 | O22: =IFERROR(E22/E16,"") -> 0.042640181 | P22: =IFERROR(F22/F16,"") -> 0.042640181 | Q22: =IFERROR(G22/G16,"") -> 0.020180617 | R22: =IFERROR(H22/H16,"") -> 0.043510531 | S22: =IFERROR(I22/I16,"") -> 0.16296069 | T22: =IFERROR(J22/J16,"") -> 0.18665338
A23: UZUN VADELİ YÜKÜMLÜLÜKLER / NON-CURRENT LIABILITIES
A24: Uzun Vadeli Finansal Borçlar (LT borrowings + lease LT) | B24: 2624731 | C24: 2263656.6 | D24: 1729403.6 | E24: 946201.18 | F24: 655437.57 | G24: 755803.87 | H24: 458341.85 | I24: 398374.89 | J24: 292951.92 | L24: =IFERROR(B24/B16,"") -> 0.12905161 | M24: =IFERROR(C24/C16,"") -> 0.11677651 | N24: =IFERROR(D24/D16,"") -> 0.11677651 | O24: =IFERROR(E24/E16,"") -> 0.071549487 | P24: =IFERROR(F24/F16,"") -> 0.071557921 | Q24: =IFERROR(G24/G16,"") -> 0.086259542 | R24: =IFERROR(H24/H16,"") -> 0.18583749 | S24: =IFERROR(I24/I16,"") -> 0.22537793 | T24: =IFERROR(J24/J16,"") -> 0.18076549
A25: Diğer UV Yükümlülükler (ETVergi, uzun vad. karşılıklar) | B25: 2699075.1 | C25: 2377697.3 | D25: 1816529.1 | E25: 1560473.6 | F25: 1080742 | G25: 888643.71 | H25: 10466.605 | I25: 83477.477 | J25: 97935.405
A26: UV YÜKÜMLÜLÜKLER TOPLAM (TOTAL NON-CURRENT LIABILITIES) | B26: =SUM(B24:B25) -> 5323806.1 | C26: =SUM(C24:C25) -> 4641353.9 | D26: =SUM(D24:D25) -> 3545932.7 | E26: =SUM(E24:E25) -> 2506674.7 | F26: =SUM(F24:F25) -> 1736179.6 | G26: =SUM(G24:G25) -> 1644447.6 | H26: =SUM(H24:H25) -> 468808.46 | I26: =SUM(I24:I25) -> 481852.36 | J26: =SUM(J24:J25) -> 390887.33 | L26: =IFERROR(B26/B16,"") -> 0.26175853 | M26: =IFERROR(C26/C16,"") -> 0.2394361 | N26: =IFERROR(D26/D16,"") -> 0.2394361 | O26: =IFERROR(E26/E16,"") -> 0.18954879 | P26: =IFERROR(F26/F16,"") -> 0.18954879 | Q26: =IFERROR(G26/G16,"") -> 0.18768003 | R26: =IFERROR(H26/H16,"") -> 0.19008124 | S26: =IFERROR(I26/I16,"") -> 0.27260475 | T26: =IFERROR(J26/J16,"") -> 0.24119637
A27: TOPLAM YÜKÜMLÜLÜKLER (TOTAL LIABILITIES) | B27: =B22+B26 -> 6209414.9 | C27: =C22+C26 -> 5697562.9 | D27: =D22+D26 -> 4352862.4 | E27: =E22+E26 -> 3070566.8 | F27: =F22+F26 -> 2126744 | G27: =G22+G26 -> 1821269.6 | H27: =H22+H26 -> 576121.02 | I27: =I22+I26 -> 769899.41 | J27: =J22+J26 -> 693381.28 | L27: =IFERROR(B27/B16,"") -> 0.30530175 | M27: =IFERROR(C27/C16,"") -> 0.29392334 | N27: =IFERROR(D27/D16,"") -> 0.29392334 | O27: =IFERROR(E27/E16,"") -> 0.23218897 | P27: =IFERROR(F27/F16,"") -> 0.23218897 | Q27: =IFERROR(G27/G16,"") -> 0.20786065 | R27: =IFERROR(H27/H16,"") -> 0.23359177 | S27: =IFERROR(I27/I16,"") -> 0.43556544 | T27: =IFERROR(J27/J16,"") -> 0.42784975
A28: ÖZKAYNAKLAR / EQUITY
A29: Ödenmiş Sermaye (Paid-in capital) | B29: 540000 | C29: 540000 | D29: 540000 | E29: 540000 | F29: 540000 | G29: 534791.46 | H29: 534791.46 | I29: 534791.46 | J29: 534791.46 | L29: =IFERROR(B29/B16,"") -> 0.02655048 | M29: =IFERROR(C29/C16,"") -> 0.02785728 | N29: =IFERROR(D29/D16,"") -> 0.036463042 | O29: =IFERROR(E29/E16,"") -> 0.040833518 | P29: =IFERROR(F29/F16,"") -> 0.058954932 | Q29: =IFERROR(G29/G16,"") -> 0.061035499 | R29: =IFERROR(H29/H16,"") -> 0.21683445 | S29: =IFERROR(I29/I16,"") -> 0.30255469 | T29: =IFERROR(J29/J16,"") -> 0.32999217
A30: Sermaye Düzeltme Farkları / SAG (Capital adj. differences) | B30: 4891623.8 | C30: 4891623.8 | D30: 3609688.4 | E30: 3609688.4 | F30: 2334168 | G30: 2332832.1 | H30: 0 | I30: 0 | J30: 0 | L30: =IFERROR(B30/B16,"") -> 0.24050918 | M30: =IFERROR(C30/C16,"") -> 0.25234691 | N30: =IFERROR(D30/D16,"") -> 0.24374115 | O30: =IFERROR(E30/E16,"") -> 0.27295607 | P30: =IFERROR(F30/F16,"") -> 0.25483466 | Q30: =IFERROR(G30/G16,"") -> 0.26624504 | R30: =IFERROR(H30/H16,"") -> 0 | S30: =IFERROR(I30/I16,"") -> 0 | T30: =IFERROR(J30/J16,"") -> 0
A31: Diğer Özkaynak (Primler, OCI, Yedekler) | B31: 592655.15 | C31: 532059.72 | D31: 406486.56 | E31: 165439.94 | F31: 114586.75 | G31: 170048.53 | H31: 44966.711 | I31: 29794.936 | J31: 19975.93
A32: Geçmiş Yıl + Net Dönem Karı (Retained + Net profit) | B32: 8104921.7 | C32: 7723273.7 | D32: 5900478.5 | E32: 5838734.8 | F32: 4044040.3 | G32: 3903032.4 | H32: 1310479.2 | I32: 433100.29 | J32: 372469.97
A33: ÖZKAYNAKLAR TOPLAM (TOTAL EQUITY) | B33: =SUM(B29:B32) -> 14129201 | C33: =SUM(C29:C32) -> 13686957 | D33: =SUM(D29:D32) -> 10456654 | E33: =SUM(E29:E32) -> 10153863 | F33: =SUM(F29:F32) -> 7032795.1 | G33: =SUM(G29:G32) -> 6940704.5 | H33: =SUM(H29:H32) -> 1890237.4 | I33: =SUM(I29:I32) -> 997686.69 | J33: =SUM(J29:J32) -> 927237.36 | L33: =IFERROR(B33/B16,"") -> 0.69469825 | M33: =IFERROR(C33/C16,"") -> 0.70607666 | N33: =IFERROR(D33/D16,"") -> 0.70607666 | O33: =IFERROR(E33/E16,"") -> 0.76781103 | P33: =IFERROR(F33/F16,"") -> 0.76781103 | Q33: =IFERROR(G33/G16,"") -> 0.79213935 | R33: =IFERROR(H33/H16,"") -> 0.76640823 | S33: =IFERROR(I33/I16,"") -> 0.56443456 | T33: =IFERROR(J33/J16,"") -> 0.57215025
A34: TOPLAM KAYNAKLAR (TOTAL LIAB. + EQUITY) | B34: =B27+B33 -> 20338616 | C34: =C27+C33 -> 19384520 | D34: =D27+D33 -> 14809516 | E34: =E27+E33 -> 13224430 | F34: =F27+F33 -> 9159539.1 | G34: =G27+G33 -> 8761974.1 | H34: =H27+H33 -> 2466358.4 | I34: =I27+I33 -> 1767586.1 | J34: =J27+J33 -> 1620618.6 | L34: =IFERROR(B34/B16,"") -> 1 | M34: =IFERROR(C34/C16,"") -> 1 | N34: =IFERROR(D34/D16,"") -> 1 | O34: =IFERROR(E34/E16,"") -> 1 | P34: =IFERROR(F34/F16,"") -> 1 | Q34: =IFERROR(G34/G16,"") -> 1 | R34: =IFERROR(H34/H16,"") -> 1 | S34: =IFERROR(I34/I16,"") -> 1 | T34: =IFERROR(J34/J16,"") -> 1
L39: YATAY ANALİZ (Aynı SAG YoY %)
K40: KALEM | L40: 2025/2024(SAG) | M40: 2024/2023(SAG) | N40: 2023/2022(SAG) | O40: 2022/2021(Nom) | P40: 2021/2020(Nom)
K41: Nakit ve Nakit Benzerleri | L41: =IFERROR((B5-C5)/ABS(C5),"-") -> -0.3120816 | M41: =IFERROR((D5-E5)/ABS(E5),"-") -> 12.835146 | N41: =IFERROR((F5-G5)/ABS(G5),"-") -> -0.93922311 | O41: =IFERROR((H5-I5)/ABS(I5),"-") -> 3.1472622 | P41: =IFERROR((I5-J5)/ABS(J5),"-") -> 1.4033249
K42: Finansal Yatırımlar KV | L42: =IFERROR((B6-C6)/ABS(C6),"-") -> - | M42: =IFERROR((D6-E6)/ABS(E6),"-") -> -1 | N42: =IFERROR((F6-G6)/ABS(G6),"-") -> -0.29772185 | O42: =IFERROR((H6-I6)/ABS(I6),"-") -> - | P42: =IFERROR((I6-J6)/ABS(J6),"-") -> -
K43: Ticari Alacaklar | L43: =IFERROR((B7-C7)/ABS(C7),"-") -> -0.012200023 | M43: =IFERROR((D7-E7)/ABS(E7),"-") -> 0.10160652 | N43: =IFERROR((F7-G7)/ABS(G7),"-") -> -0.0022524102 | O43: =IFERROR((H7-I7)/ABS(I7),"-") -> -0.0022983622 | P43: =IFERROR((I7-J7)/ABS(J7),"-") -> 1.422395
K44: Stoklar | L44: =IFERROR((B8-C8)/ABS(C8),"-") -> -0.5249113 | M44: =IFERROR((D8-E8)/ABS(E8),"-") -> 0 | N44: =IFERROR((F8-G8)/ABS(G8),"-") -> -0.0057618301 | O44: =IFERROR((H8-I8)/ABS(I8),"-") -> -0.019552778 | P44: =IFERROR((I8-J8)/ABS(J8),"-") -> -0.49847836
...

Sheet GWIND_PLS
A1: GALATA WIND ENERJİ A.Ş. — GELİR TABLOSU / INCOME STATEMENT (BİN TL) | L1: DİKEY ANALİZ (% Hasılat)
A2: KALEM (BİN TL) | B2: 31.12.2025 (2025 SAG) | C2: 31.12.2024 (2025 SAG) | D2: 31.12.2024 (2024 SAG) | E2: 31.12.2023 (2024 SAG) | F2: 31.12.2023 (2023 SAG) | G2: 31.12.2022 (2023 SAG) | H2: 31.12.2022 (Nominal) | I2: 31.12.2021 (Nominal) | J2: 31.12.2020 (Nominal) | L2: 31.12.2025 (2025 SAG) | M2: 31.12.2024 (2025 SAG) | N2: 31.12.2024 (2024 SAG) | O2: 31.12.2023 (2024 SAG) | P2: 31.12.2023 (2023 SAG) | Q2: 31.12.2022 (2023 SAG) | R2: 31.12.2022 (Nominal) | S2: 31.12.2021 (Nominal) | T2: 31.12.2020 (Nominal)
A3: GELİR TABLOSU / INCOME STATEMENT (TFRS - TMS29 Satın Alma Gücü Düzeltmeli)
A4: Hasılat (Net Revenue) | B4: 2939691.8 | C4: 3094818.2 | D4: 2364400 | E4: 2684048.7 | F4: 1859032.8 | G4: 2296830 | H4: 1187271.8 | I4: 540226.28 | J4: 335201.95 | L4: =IFERROR(B4/B4,"") -> 1 | M4: =IFERROR(C4/C4,"") -> 1 | N4: =IFERROR(D4/D4,"") -> 1 | O4: =IFERROR(E4/E4,"") -> 1 | P4: =IFERROR(F4/F4,"") -> 1 | Q4: =IFERROR(G4/G4,"") -> 1 | R4: =IFERROR(H4/H4,"") -> 1 | S4: =IFERROR(I4/I4,"") -> 1 | T4: =IFERROR(J4/J4,"") -> 1
A5: Satışların Maliyeti (-) (Cost of sales) | B5: -1593244 | C5: -1470095.7 | D5: -1123133.6 | E5: -1087585.4 | F5: -753286.24 | G5: -652409.85 | H5: -213469.08 | I5: -145366.75 | J5: -88705.657 | L5: =IFERROR(B5/B4,"") -> -0.54197654 | M5: =IFERROR(C5/C4,"") -> -0.47501845 | N5: =IFERROR(D5/D4,"") -> -0.47501845 | O5: =IFERROR(E5/E4,"") -> -0.40520331 | P5: =IFERROR(F5/F4,"") -> -0.40520331 | Q5: =IFERROR(G5/G4,"") -> -0.28404795 | R5: =IFERROR(H5/H4,"") -> -0.17979798 | S5: =IFERROR(I5/I4,"") -> -0.26908493 | T5: =IFERROR(J5/J4,"") -> -0.26463347
A6: BRÜT KAR / GROSS PROFIT | B6: =B4+B5 -> 1346447.8 | C6: =C4+C5 -> 1624722.4 | D6: =D4+D5 -> 1241266.3 | E6: =E4+E5 -> 1596463.3 | F6: =F4+F5 -> 1105746.6 | G6: =G4+G5 -> 1644420.2 | H6: =H4+H5 -> 973802.75 | I6: =I4+I5 -> 394859.53 | J6: =J4+J5 -> 246496.3 | L6: =IFERROR(B6/B4,"") -> 0.45802346 | M6: =IFERROR(C6/C4,"") -> 0.52498155 | N6: =IFERROR(D6/D4,"") -> 0.52498155 | O6: =IFERROR(E6/E4,"") -> 0.59479669 | P6: =IFERROR(F6/F4,"") -> 0.59479669 | Q6: =IFERROR(G6/G4,"") -> 0.71595205 | R6: =IFERROR(H6/H4,"") -> 0.82020202 | S6: =IFERROR(I6/I4,"") -> 0.73091507 | T6: =IFERROR(J6/J4,"") -> 0.73536653
A7: Genel Yönetim Giderleri (-) (G&A expenses) | B7: -277480.55 | C7: -275923.04 | D7: -174481.46 | E7: -91519.475 | F7: -63388.457 | G7: -45956.042 | H7: -24713.014 | I7: -23918.82 | J7: -14143.854 | L7: =IFERROR(B7/B4,"") -> -0.094391037 | M7: =IFERROR(C7/C4,"") -> -0.089156464 | N7: =IFERROR(D7/D4,"") -> -0.073795241 | O7: =IFERROR(E7/E4,"") -> -0.034097546 | P7: =IFERROR(F7/F4,"") -> -0.034097546 | Q7: =IFERROR(G7/G4,"") -> -0.020008464 | R7: =IFERROR(H7/H4,"") -> -0.020814959 | S7: =IFERROR(I7/I4,"") -> -0.044275558 | T7: =IFERROR(J7/J4,"") -> -0.042195023
A8: Pazarlama Giderleri (-) (Marketing expenses) | B8: -21122.877 | C8: -20363.625 | D8: -51877.614 | E8: -37178.785 | F8: -25750.867 | G8: -21280.791 | H8: -10884.445 | I8: -6034.512 | J8: -3100.522 | L8: =IFERROR(B8/B4,"") -> -0.0071854054 | M8: =IFERROR(C8/C4,"") -> -0.00657991 | N8: =IFERROR(D8/D4,"") -> -0.021941133 | O8: =IFERROR(E8/E4,"") -> -0.013851755 | P8: =IFERROR(F8/F4,"") -> -0.013851755 | Q8: =IFERROR(G8/G4,"") -> -0.0092652877 | R8: =IFERROR(H8/H4,"") -> -0.0091676099 | S8: =IFERROR(I8/I4,"") -> -0.011170341 | T8: =IFERROR(J8/J4,"") -> -0.0092497134
A9: Esas Faaliyetlerden Diğer Gelirler (Other op. income) | B9: 531728.09 | C9: 184347.62 | D9: 140839.13 | E9: 661558.64 | F9: 458210.46 | G9: 351011.99 | H9: 181818.13 | I9: 59967.787 | J9: 49577.647 | L9: =IFERROR(B9/B4,"") -> 0.18087886 | M9: =IFERROR(C9/C4,"") -> 0.059566542 | N9: =IFERROR(D9/D4,"") -> 0.059566542 | O9: =IFERROR(E9/E4,"") -> 0.24647788 | P9: =IFERROR(F9/F4,"") -> 0.24647788 | Q9: =IFERROR(G9/G4,"") -> 0.15282454 | R9: =IFERROR(H9/H4,"") -> 0.15313943 | S9: =IFERROR(I9/I4,"") -> 0.11100494 | T9: =IFERROR(J9/J4,"") -> 0.14790381
A10: Esas Faaliyetlerden Diğer Giderler (-) (Other op. exp.) | B10: -40727.291 | C10: -39299.627 | D10: -30024.393 | E10: -3175.88 | F10: -2199.686 | G10: -23441.626 | H10: -13469.879 | I10: -19537.816 | J10: -4522.369 | L10: =IFERROR(B10/B4,"") -> -0.013854273 | M10: =IFERROR(C10/C4,"") -> -0.012698525 | N10: =IFERROR(D10/D4,"") -> -0.012698525 | O10: =IFERROR(E10/E4,"") -> -0.0011832423 | P10: =IFERROR(F10/F4,"") -> -0.0011832422 | Q10: =IFERROR(G10/G4,"") -> -0.010206078 | R10: =IFERROR(H10/H4,"") -> -0.011345236 | S10: =IFERROR(I10/I4,"") -> -0.036165986 | T10: =IFERROR(J10/J4,"") -> -0.013491476
A11: FAALİYET KARI (EBIT) / OPERATING PROFIT | B11: =B6+B7+B8+B9+B10 -> 1538845.2 | C11: =C6+C7+C8+C9+C10 -> 1473483.7 | D11: =D6+D7+D8+D9+D10 -> 1125722 | E11: =E6+E7+E8+E9+E10 -> 2126147.8 | F11: =F6+F7+F8+F9+F10 -> 1472618 | G11: =G6+G7+G8+G9+G10 -> 1904753.7 | H11: =H6+H7+H8+H9+H10 -> 1106553.5 | I11: =I6+I7+I8+I9+I10 -> 405336.17 | J11: =J6+J7+J8+J9+J10 -> 274307.2 | L11: =IFERROR(B11/B4,"") -> 0.52347161 | M11: =IFERROR(C11/C4,"") -> 0.47611319 | N11: =IFERROR(D11/D4,"") -> 0.47611319 | O11: =IFERROR(E11/E4,"") -> 0.79214203 | P11: =IFERROR(F11/F4,"") -> 0.79214203 | Q11: =IFERROR(G11/G4,"") -> 0.82929676 | R11: =IFERROR(H11/H4,"") -> 0.93201364 | S11: =IFERROR(I11/I4,"") -> 0.75030813 | T11: =IFERROR(J11/J4,"") -> 0.81833413
A12: (+) Amortisman ve İtfa (D&A add-back) | B12: 963755.74 | C12: 812716.39 | D12: 620904.52 | E12: 560777.8 | F12: 388407.38 | G12: 380365.88 | H12: 64577.672 | I12: 63161.961 | J12: 34544.685 | L12: =IFERROR(B12/B4,"") -> 0.32784245 | M12: =IFERROR(C12/C4,"") -> 0.26260554 | N12: =IFERROR(D12/D4,"") -> 0.26260554 | O12: =IFERROR(E12/E4,"") -> 0.20892981 | P12: =IFERROR(F12/F4,"") -> 0.20892981 | Q12: =IFERROR(G12/G4,"") -> 0.16560471 | R12: =IFERROR(H12/H4,"") -> 0.054391649 | S12: =IFERROR(I12/I4,"") -> 0.1169176 | T12: =IFERROR(J12/J4,"") -> 0.10305634
A13: FAVÖK / EBITDA | B13: =B11+B12 -> 2502600.9 | C13: =C11+C12 -> 2286200.1 | D13: =D11+D12 -> 1746626.5 | E13: =E11+E12 -> 2686925.6 | F13: =F11+F12 -> 1861025.4 | G13: =G11+G12 -> 2285119.6 | H13: =H11+H12 -> 1171131.2 | I13: =I11+I12 -> 468498.13 | J13: =J11+J12 -> 308851.88 | L13: =IFERROR(B13/B4,"") -> 0.85131405 | M13: =IFERROR(C13/C4,"") -> 0.73871873 | N13: =IFERROR(D13/D4,"") -> 0.73871873 | O13: =IFERROR(E13/E4,"") -> 1.0010718 | P13: =IFERROR(F13/F4,"") -> 1.0010718 | Q13: =IFERROR(G13/G4,"") -> 0.99490148 | R13: =IFERROR(H13/H4,"") -> 0.98640529 | S13: =IFERROR(I13/I4,"") -> 0.86722573 | T13: =IFERROR(J13/J4,"") -> 0.92139046
A14: Finansman Giderleri (-) (Finance expenses, net) | B14: -513747.36 | C14: -259170.25 | D14: -198002.63 | E14: -515294.42 | F14: -356904.56 | G14: -327852.6 | H14: -171205.87 | I14: -208984.41 | J14: -75592.598 | L14: =IFERROR(B14/B4,"") -> -0.17476232 | M14: =IFERROR(C14/C4,"") -> -0.083743289 | N14: =IFERROR(D14/D4,"") -> -0.083743289 | O14: =IFERROR(E14/E4,"") -> -0.191984 | P14: =IFERROR(F14/F4,"") -> -0.191984 | Q14: =IFERROR(G14/G4,"") -> -0.14274134 | R14: =IFERROR(H14/H4,"") -> -0.14420107 | S14: =IFERROR(I14/I4,"") -> -0.38684607 | T14: =IFERROR(J14/J4,"") -> -0.2255136
A15: Net Parasal Pozisyon Kazancı/(Kaybı) (TMS29 Monetary gain/loss) | B15: 335341.09 | C15: 360389.54 | D15: 275332.82 | E15: -159758.03 | F15: -110652.02 | G15: 27868.825 | H15: 0 | I15: 0 | J15: 0 | L15: =IFERROR(B15/B4,"") -> 0.11407355 | M15: =IFERROR(C15/C4,"") -> 0.11644934 | N15: =IFERROR(D15/D4,"") -> 0.11644934 | O15: =IFERROR(E15/E4,"") -> -0.059521287 | P15: =IFERROR(F15/F4,"") -> -0.059521287 | Q15: =IFERROR(G15/G4,"") -> 0.012133604 | R15: =IFERROR(H15/H4,"") -> 0 | S15: =IFERROR(I15/I4,"") -> 0 | T15: =IFERROR(J15/J4,"") -> 0
A16: VERGİ ÖNCESİ KAR / PROFIT BEFORE TAX (PBT) | B16: =B11+B14+B15 -> 1360438.9 | C16: =C11+C14+C15 -> 1574703 | D16: =D11+D14+D15 -> 1203052.2 | E16: =E11+E14+E15 -> 1451095.4 | F16: =F11+F14+F15 -> 1005061.4 | G16: =G11+G14+G15 -> 1604769.9 | H16: =H11+H14+H15 -> 935347.67 | I16: =I11+I14+I15 -> 196351.76 | J16: =J11+J14+J15 -> 198714.6 | L16: =IFERROR(B16/B4,"") -> 0.46278284 | M16: =IFERROR(C16/C4,"") -> 0.50881924 | N16: =IFERROR(D16/D4,"") -> 0.50881924 | O16: =IFERROR(E16/E4,"") -> 0.54063674 | P16: =IFERROR(F16/F4,"") -> 0.54063674 | Q16: =IFERROR(G16/G4,"") -> 0.69868902 | R16: =IFERROR(H16/H4,"") -> 0.78781257 | S16: =IFERROR(I16/I4,"") -> 0.36346206 | T16: =IFERROR(J16/J4,"") -> 0.59282053
A17: Dönem Vergi Gideri (-) (Current tax expense) | B17: -192352.45 | C17: -145137.72 | D17: -110883.29 | E17: -260872.27 | F17: -180686.03 | G17: -233889.62 | H17: -114981.52 | I17: -47052.651 | J17: -27295.599 | L17: =IFERROR(B17/B4,"") -> -0.065432862 | M17: =IFERROR(C17/C4,"") -> -0.046897009 | N17: =IFERROR(D17/D4,"") -> -0.046897009 | O17: =IFERROR(E17/E4,"") -> -0.097193568 | P17: =IFERROR(F17/F4,"") -> -0.097193568 | Q17: =IFERROR(G17/G4,"") -> -0.10183149 | R17: =IFERROR(H17/H4,"") -> -0.096845156 | S17: =IFERROR(I17/I4,"") -> -0.087098042 | T17: =IFERROR(J17/J4,"") -> -0.08143031
A18: Ertelenmiş Vergi Gel./(Gid.) (Deferred tax income/(expense)) | B18: -322658.89 | C18: -337386.54 | D18: -257758.84 | E18: -289952.52 | F18: -200827.67 | G18: 93746.871 | H18: 223589.79 | I18: 21613.755 | J18: -15062.46 | L18: =IFERROR(B18/B4,"") -> -0.10975943 | M18: =IFERROR(C18/C4,"") -> -0.1090166 | N18: =IFERROR(D18/D4,"") -> -0.1090166 | O18: =IFERROR(E18/E4,"") -> -0.10802804 | P18: =IFERROR(F18/F4,"") -> -0.10802804 | Q18: =IFERROR(G18/G4,"") -> 0.040815763 | R18: =IFERROR(H18/H4,"") -> 0.18832232 | S18: =IFERROR(I18/I4,"") -> 0.040008707 | T18: =IFERROR(J18/J4,"") -> -0.044935478
A19: Toplam Vergi (-) / Total Tax Expense | B19: =B17+B18 -> -515011.34 | C19: =C17+C18 -> -482524.26 | D19: =D17+D18 -> -368642.12 | E19: =E17+E18 -> -550824.79 | F19: =F17+F18 -> -381513.7 | G19: =G17+G18 -> -140142.75 | H19: =H17+H18 -> 108608.26 | I19: =I17+I18 -> -25438.896 | J19: =J17+J18 -> -42358.059 | L19: =IFERROR(B19/B4,"") -> -0.17519229 | M19: =IFERROR(C19/C4,"") -> -0.15591361 | N19: =IFERROR(D19/D4,"") -> -0.15591361 | O19: =IFERROR(E19/E4,"") -> -0.20522161 | P19: =IFERROR(F19/F4,"") -> -0.20522161 | Q19: =IFERROR(G19/G4,"") -> -0.061015723 | R19: =IFERROR(H19/H4,"") -> 0.091477166 | S19: =IFERROR(I19/I4,"") -> -0.047089335 | T19: =IFERROR(J19/J4,"") -> -0.12636579
A20: NET DÖNEM KARI / NET PROFIT | B20: =B16+B19 -> 845427.57 | C20: =C16+C19 -> 1092178.8 | D20: =D16+D19 -> 834410.07 | E20: =E16+E19 -> 900270.56 | F20: =F16+F19 -> 623547.74 | G20: =G16+G19 -> 1464627.2 | H20: =H16+H19 -> 1043955.9 | I20: =I16+I19 -> 170912.86 | J20: =J16+J19 -> 156356.54 | L20: =IFERROR(B20/B4,"") -> 0.28759055 | M20: =IFERROR(C20/C4,"") -> 0.35290564 | N20: =IFERROR(D20/D4,"") -> 0.35290564 | O20: =IFERROR(E20/E4,"") -> 0.33541513 | P20: =IFERROR(F20/F4,"") -> 0.33541513 | Q20: =IFERROR(G20/G4,"") -> 0.6376733 | R20: =IFERROR(H20/H4,"") -> 0.87928974 | S20: =IFERROR(I20/I4,"") -> 0.31637272 | T20: =IFERROR(J20/J4,"") -> 0.46645475
A21: Hisse Başına Kazanç / EPS (TL) | B21: =IFERROR(B20/GWIND_BS!B29,0) -> 1.5656066 | C21: =IFERROR(C20/GWIND_BS!C29,0) -> 2.0225533 | D21: =IFERROR(D20/GWIND_BS!D29,0) -> 1.5452038 | E21: =IFERROR(E20/GWIND_BS!E29,0) -> 1.6671677 | F21: =IFERROR(F20/GWIND_BS!F29,0) -> 1.154718 | G21: =IFERROR(G20/GWIND_BS!G29,0) -> 2.7386884 | H21: =IFERROR(H20/GWIND_BS!H29,0) -> 1.9520804 | I21: =IFERROR(I20/GWIND_BS!I29,0) -> 0.31958786 | J21: =IFERROR(J20/GWIND_BS!J29,0) -> 0.29236918
L24: YATAY ANALİZ (Aynı SAG YoY %)
K25: KALEM | L25: 2025/2024(SAG) | M25: 2024/2023(SAG) | N25: 2023/2022(SAG) | O25: 2022/2021(Nom) | P25: 2021/2020(Nom)
K26: Hasılat (Net Revenue) | L26: =IFERROR((B4-C4)/ABS(C4),"-") -> -0.050124557 | M26: =IFERROR((D4-E4)/ABS(E4),"-") -> -0.11909201 | N26: =IFERROR((F4-G4)/ABS(G4),"-") -> -0.19060933 | O26: =IFERROR((H4-I4)/ABS(I4),"-") -> 1.1977306 | P26: =IFERROR((I4-J4)/ABS(J4),"-") -> 0.61164418
K27: Satışların Maliyeti | L27: =IFERROR((B5-C5)/ABS(C5),"-") -> -0.083768847 | M27: =IFERROR((D5-E5)/ABS(E5),"-") -> -0.032685424 | N27: =IFERROR((F5-G5)/ABS(G5),"-") -> -0.1546212 | O27: =IFERROR((H5-I5)/ABS(I5),"-") -> -0.46848629 | P27: =IFERROR((I5-J5)/ABS(J5),"-") -> -0.63875399
K28: BRÜT KAR | L28: =IFERROR((B6-C6)/ABS(C6),"-") -> -0.17127517 | M28: =IFERROR((D6-E6)/ABS(E6),"-") -> -0.2224899 | N28: =IFERROR((F6-G6)/ABS(G6),"-") -> -0.32757663 | O28: =IFERROR((H6-I6)/ABS(I6),"-") -> 1.4662005 | P28: =IFERROR((I6-J6)/ABS(J6),"-") -> 0.60188828
K29: Genel Yönetim Giderleri | L29: =IFERROR((B7-C7)/ABS(C7),"-") -> -0.0056447297 | M29: =IFERROR((D7-E7)/ABS(E7),"-") -> -0.90649548 | N29: =IFERROR((F7-G7)/ABS(G7),"-") -> -0.37932803 | O29: =IFERROR((H7-I7)/ABS(I7),"-") -> -0.033203728 | P29: =IFERROR((I7-J7)/ABS(J7),"-") -> -0.6911105
K30: Pazarlama Giderleri | L30: =IFERROR((B8-C8)/ABS(C8),"-") -> -0.037284717 | M30: =IFERROR((D8-E8)/ABS(E8),"-") -> -0.39535528 | N30: =IFERROR((F8-G8)/ABS(G8),"-") -> -0.21005215 | O30: =IFERROR((H8-I8)/ABS(I8),"-") -> -0.80369929 | P30: =IFERROR((I8-J8)/ABS(J8),"-") -> -0.94628904
K31: Esas Faaliyetlerden Diğer Gelirler | L31: =IFERROR((B9-C9)/ABS(C9),"-") -> 1.8843774 | M31: =IFERROR((D9-E9)/ABS(E9),"-") -> -0.78711013 | N31: =IFERROR((F9-G9)/ABS(G9),"-") -> 0.30539833 | O31: =IFERROR((H9-I9)/ABS(I9),"-") -> 2.03193 | P31: =IFERROR((I9-J9)/ABS(J9),"-") -> 0.20957308
K32: Esas Faaliyetlerden Diğer Giderler | L32: =IFERROR((B10-C10)/ABS(C10),"-") -> -0.036327673 | M32: =IFERROR((D10-E10)/ABS(E10),"-") -> -8.4538814 | N32: =IFERROR((F10-G10)/ABS(G10),"-") -> 0.90616325 | O32: =IFERROR((H10-I10)/ABS(I10),"-") -> 0.31057397 | P32: =IFERROR((I10-J10)/ABS(J10),"-") -> -3.3202613
K33: FAALİYET KARI (EBIT) | L33: =IFERROR((B11-C11)/ABS(C11),"-") -> 0.044358434 | M33: =IFERROR((D11-E11)/ABS(E11),"-") -> -0.47053445 | N33: =IFERROR((F11-G11)/ABS(G11),"-") -> -0.22687221 | O33: =IFERROR((H11-I11)/ABS(I11),"-") -> 1.729965 | P33: =IFERROR((I11-J11)/ABS(J11),"-") -> 0.47767236
K34: (+) Amortisman ve İtfa | L34: =IFERROR((B12-C12)/ABS(C12),"-") -> 0.18584509 | M34: =IFERROR((D12-E12)/ABS(E12),"-") -> 0.10722022 | N34: =IFERROR((F12-G12)/ABS(G12),"-") -> 0.021141486 | O34: =IFERROR((H12-I12)/ABS(I12),"-") -> 0.022413981 | P34: =IFERROR((I12-J12)/ABS(J12),"-") -> 0.82841329
K35: FAVÖK / EBITDA | L35: =IFERROR((B13-C13)/ABS(C13),"-") -> 0.094655223 | M35: =IFERROR((D13-E13)/ABS(E13),"-") -> -0.34995352 | N35: =IFERROR((F13-G13)/ABS(G13),"-") -> -0.1855895 | O35: =IFERROR((H13-I13)/ABS(I13),"-") -> 1.4997564 | P35: =IFERROR((I13-J13)/ABS(J13),"-") -> 0.51690228
K36: Finansman Giderleri (Net) | L36: =IFERROR((B14-C14)/ABS(C14),"-") -> -0.98227751 | M36: =IFERROR((D14-E14)/ABS(E14),"-") -> 0.61574855 | N36: =IFERROR((F14-G14)/ABS(G14),"-") -> -0.088612864 | O36: =IFERROR((H14-I14)/ABS(I14),"-") -> 0.18077206 | P36: =IFERROR((I14-J14)/ABS(J14),"-") -> -1.7646148
K37: Net Parasal Poz. Kazancı (TMS29) | L37: =IFERROR((B15-C15)/ABS(C15),"-") -> -0.06950381 | M37: =IFERROR((D15-E15)/ABS(E15),"-") -> 2.7234364 | N37: =IFERROR((F15-G15)/ABS(G15),"-") -> -4.9704589 | O37: =IFERROR((H15-I15)/ABS(I15),"-") -> - | P37: =IFERROR((I15-J15)/ABS(J15),"-") -> -
... K42: NET DÖNEM KARI | L42: =IFERROR((B20-C20)/ABS(C20),"-") -> -0.22592566 | M42: =IFERROR((D20-E20)/ABS(E20),"-") -> -0.073156328 | N42: =IFERROR((F20-G20)/ABS(G20),"-") -> -0.57426181 | O42: =IFERROR((H20-I20)/ABS(I20),"-") -> 5.1081181 | P42: =IFERROR((I20-J20)/ABS(J20),"-") -> 0.093096949

Sheet GWIND_CFS
A1: GALATA WIND ENERJİ A.Ş. — NAKİT AKIŞ TABLOSU / CASH FLOW (BİN TL) | L1: DİKEY ANALİZ (% İşletme Nakit Akışı)
A2: KALEM (BİN TL) | B2: 31.12.2025 (2025 SAG) | C2: 31.12.2024 (2025 SAG) | D2: 31.12.2024 (2024 SAG) | E2: 31.12.2023 (2024 SAG) | F2: 31.12.2023 (2023 SAG) | G2: 31.12.2022 (2023 SAG) | H2: 31.12.2022 (Nominal) | I2: 31.12.2021 (Nominal) | J2: 31.12.2020 (Nominal) | L2: 31.12.2025 (2025 SAG) | M2: 31.12.2024 (2025 SAG) | N2: 31.12.2024 (2024 SAG) | O2: 31.12.2023 (2024 SAG) | P2: 31.12.2023 (2023 SAG) | Q2: 31.12.2022 (2023 SAG) | R2: 31.12.2022 (Nominal) | S2: 31.12.2021 (Nominal) | T2: 31.12.2020 (Nominal)
A3: NAKİT AKIŞ TABLOSU / CASH FLOW STATEMENT (TFRS)
A4: Dönem Karı / Net profit | B4: 845427.56 | C4: 1092178.8 | D4: 834410.07 | E4: 900270.56 | F4: 623547.73 | G4: 1464627.2 | H4: 1043955.9 | I4: 170912.86 | J4: 156356.54
A5: (+) Amortisman ve İtfa / Depreciation & amortization | B5: 963755.74 | C5: 812716.39 | D5: 620904.52 | E5: 560777.8 | F5: 388407.38 | G5: 380365.88 | H5: 64577.672 | I5: 63161.961 | J5: 34544.685
A6: Karşılıklar ve Düzeltmeler / Provisions & adjustments | B6: 20107.924 | C6: 12896.045 | D6: 9852.408 | E6: 33146.902 | F6: 22958.294 | G6: 13004.747 | H6: 1405.209 | I6: 11677.165 | J6: -110.232
A7: Diğer Düzeltmeler (Faiz, Vergi, GUD, Kur) / Other adj. | B7: 607627.29 | C7: 627006 | D7: 534652.18 | E7: 382028.84 | F7: 262453.58 | G7: 174805.81 | H7: -103795.68 | I7: 101547.09 | J7: 92925.322
A8: Parasal Poz. Düzeltmesi (TMS29) / Monetary adj. | B8: -746356.79 | C8: -313201.42 | D8: -239281.73 | E8: 474745.82 | F8: 323838.87 | G8: -1798306.2 | H8: 0 | I8: 0 | J8: 0
A9: İşletme Sermayesi Değişimleri / Working capital changes | B9: -76683.407 | C9: -250756.5 | D9: -191574.64 | E9: 461741.94 | F9: 319812.9 | G9: 634189.37 | H9: 177579.13 | I9: -10650.368 | J9: 14922.737
A10: Diğer / Other operating adjustments | B10: 33838.034 | C10: -26401.949 | D10: -75841.663 | E10: 55055.779 | F10: 38133.058 | G10: -180477.88 | H10: -110935.93 | I10: -17156.744 | J10: -26462.685
A11: İŞLETME FAALİYETLERİNDEN NAKİT AKIŞI (OCF) | B11: =SUM(B4:B10) -> 1647716.4 | C11: =SUM(C4:C10) -> 1954437.3 | D11: =SUM(D4:D10) -> 1493121.2 | E11: =SUM(E4:E10) -> 2867767.6 | F11: =SUM(F4:F10) -> 1979151.8 | G11: =SUM(G4:G10) -> 688208.92 | H11: =SUM(H4:H10) -> 1072786.3 | I11: =SUM(I4:I10) -> 319491.96 | J11: =SUM(J4:J10) -> 272176.37 | L11: =IFERROR(B11/B11,"") -> 1 | M11: =IFERROR(C11/C11,"") -> 1 | N11: =IFERROR(D11/D11,"") -> 1 | O11: =IFERROR(E11/E11,"") -> 1 | P11: =IFERROR(F11/F11,"") -> 1 | Q11: =IFERROR(G11/G11,"") -> 1 | R11: =IFERROR(H11/H11,"") -> 1 | S11: =IFERROR(I11/I11,"") -> 1 | T11: =IFERROR(J11/J11,"") -> 1
A12: YATIRIM FAALİYETLERİNDEN NAKİT AKIŞLARI / INVESTING
A13: (-) CAPEX — Maddi+Maddi Olmayan Duran Varlık Alımları | B13: -1613690.2 | C13: -2624231.8 | D13: -2004878.2 | E13: -1898584.7 | F13: -1332027.9 | G13: -120188.28 | H13: -140695.98 | I13: -83658.89 | J13: -424660.51 | L13: =IFERROR(B13/B11,"") -> -0.97934949 | M13: =IFERROR(C13/C11,"") -> -1.3427045 | N13: =IFERROR(D13/D11,"") -> -1.3427432 | O13: =IFERROR(E13/E11,"") -> -0.66204271 | P13: =IFERROR(F13/F11,"") -> -0.67302968 | Q13: =IFERROR(G13/G11,"") -> -0.17463924 | R13: =IFERROR(H13/H11,"") -> -0.13115005 | S13: =IFERROR(I13/I11,"") -> -0.26184975 | T13: =IFERROR(J13/J11,"") -> -1.5602402
A14: Diğer Yatırım Faaliyetleri / Other investing activities | B14: -633415.97 | C14: 1375745.1 | D14: 1050861.7 | E14: -1080199.4 | F14: -731145.22 | G14: -369227.89 | H14: -117068.35 | I14: 152.455 | J14: -1050
A15: YATIRIM FAALİYETLERİNDEN NAKİT AKIŞI (ICF) | B15: =B13+B14 -> -2247106.2 | C15: =C13+C14 -> -1248486.7 | D15: =D13+D14 -> -954016.52 | E15: =E13+E14 -> -2978784 | F15: =F13+F14 -> -2063173.1 | G15: =G13+G14 -> -489416.17 | H15: =H13+H14 -> -257764.33 | I15: =I13+I14 -> -83506.435 | J15: =J13+J14 -> -425710.51 | L15: =IFERROR(B15/B11,"") -> -1.36377 | M15: =IFERROR(C15/C11,"") -> -0.63879597 | N15: =IFERROR(D15/D11,"") -> -0.63894113 | O15: =IFERROR(E15/E11,"") -> -1.0387118 | P15: =IFERROR(F15/F11,"") -> -1.0424532 | Q15: =IFERROR(G15/G11,"") -> -0.71114477 | R15: =IFERROR(H15/H11,"") -> -0.24027555 | S15: =IFERROR(I15/I11,"") -> -0.26137257 | T15: =IFERROR(J15/J11,"") -> -1.564098
A16: FİNANSMAN FAALİYETLERİNDEN NAKİT AKIŞLARI / FINANCING
A17: Borçlanmalardan/Ödemelerden Net Nakit / Net borrowings | B17: 473391.15 | C17: 1716838.9 | D17: 1311748.1 | E17: -138604.67 | F17: -96000.726 | G17: -434902.89 | H17: -267579.93 | I17: -58459.47 | J17: 86575.938 | L17: =IFERROR(B17/B11,"") -> 0.28730136 | M17: =IFERROR(C17/C11,"") -> 0.87843131 | N17: =IFERROR(D17/D11,"") -> 0.87852755 | O17: =IFERROR(E17/E11,"") -> -0.048331904 | P17: =IFERROR(F17/F11,"") -> -0.048505994 | Q17: =IFERROR(G17/G11,"") -> -0.63193439 | R17: =IFERROR(H17/H11,"") -> -0.24942519 | S17: =IFERROR(I17/I11,"") -> -0.18297634 | T17: =IFERROR(J17/J11,"") -> 0.31808764
A18: (-) Ödenen Temettüler / Dividends paid | B18: -399509.41 | C18: -695610.96 | D18: -531437.53 | E18: -761888.11 | F18: -527700.93 | G18: -330599.54 | H18: -150000 | I18: -100000 | J18: -10000 | L18: =IFERROR(B18/B11,"") -> -0.24246249 | M18: =IFERROR(C18/C11,"") -> -0.35591367 | N18: =IFERROR(D18/D11,"") -> -0.35592392 | O18: =IFERROR(E18/E11,"") -> -0.26567289 | P18: =IFERROR(F18/F11,"") -> -0.26662984 | Q18: =IFERROR(G18/G11,"") -> -0.48037671 | R18: =IFERROR(H18/H11,"") -> -0.13982281 | S18: =IFERROR(I18/I11,"") -> -0.31299692 | T18: =IFERROR(J18/J11,"") -> -0.036740883
A19: Diğer Finansman (Faiz, Diğer) / Other financing | B19: -169507.79 | C19: -91454.398 | D19: -79869.946 | E19: -28132.368 | F19: -12356.257 | G19: -112400.84 | H19: -47559.886 | I19: -37842.211 | J19: -10090.076
A20: FİNANSMAN FAALİYETLERİNDEN NAKİT AKIŞI (FCF) | B20: =SUM(B17:B19) -> -95626.048 | C20: =SUM(C17:C19) -> 929773.59 | D20: =SUM(D17:D19) -> 700440.59 | E20: =SUM(E17:E19) -> -928625.15 | F20: =SUM(F17:F19) -> -636057.91 | G20: =SUM(G17:G19) -> -877903.27 | H20: =SUM(H17:H19) -> -465139.82 | I20: =SUM(I17:I19) -> -196301.68 | J20: =SUM(J17:J19) -> 66485.862 | L20: =IFERROR(B20/B11,"") -> -0.058035503 | M20: =IFERROR(C20/C11,"") -> 0.47572443 | N20: =IFERROR(D20/D11,"") -> 0.4691117 | O20: =IFERROR(E20/E11,"") -> -0.32381464 | P20: =IFERROR(F20/F11,"") -> -0.32137904 | Q20: =IFERROR(G20/G11,"") -> -1.2756348 | R20: =IFERROR(H20/H11,"") -> -0.43358104 | S20: =IFERROR(I20/I11,"") -> -0.61441822 | T20: =IFERROR(J20/J11,"") -> 0.24427492
A21: Nakit Üzerindeki Enflasyon Etkisi / Inflation effect on cash | B21: -85066.781 | C21: -71183.487 | D21: -54383.239 | E21: -846022.19 | F21: -585974.09 | G21: 1057991.4 | H21: 0 | I21: 0 | J21: 0
A22: Yabancı Para Çevrim Farkları / FX translation differences | B22: 251605.04 | C22: 24996.678 | D22: 19097.131 | E22: 421929.74 | F22: 292238.08 | G22: 270724.79 | H22: 144048.32 | I22: 53124.901 | J22: 20493.323
A23: NAKİT NET ARTIŞ/(AZALIŞ) / Net change in cash | B23: =B11+B15+B20+B21+B22 -> -528477.58 | C23: =C11+C15+C20+C21+C22 -> 1589537.4 | D23: =D11+D15+D20+D21+D22 -> 1204259.1 | E23: =E11+E15+E20+E21+E22 -> -1463734 | F23: =F11+F15+F20+F21+F22 -> -1013815.2 | G23: =G11+G15+G20+G21+G22 -> 649605.66 | H23: =H11+H15+H20+H21+H22 -> 493930.51 | I23: =I11+I15+I20+I21+I22 -> 92808.743 | J23: =J11+J15+J20+J21+J22 -> -66554.955 | L23: =IFERROR(B23/B11,"") -> -0.32073335 | M23: =IFERROR(C23/C11,"") -> 0.81329669 | N23: =IFERROR(D23/D11,"") -> 0.80653811 | O23: =IFERROR(E23/E11,"") -> -0.51040885 | P23: =IFERROR(F23/F11,"") -> -0.51224733 | Q23: =IFERROR(G23/G11,"") -> 0.94390764 | R23: =IFERROR(H23/H11,"") -> 0.46041835 | S23: =IFERROR(I23/I11,"") -> 0.29048851 | T23: =IFERROR(J23/J11,"") -> -0.24452878
A24: Dönem Başı Nakit / Cash at beginning of period | B24: 1714149.1 | C24: 124611.66 | D24: 95201.655 | E24: 1558935.6 | F24: 1079754.1 | G24: 430148.27 | H24: 158918.75 | I24: 66110.01 | J24: 132664.96 | L24: =IFERROR(B24/B11,"") -> 1.0403181 | M24: =IFERROR(C24/C11,"") -> 0.063758332 | N24: =IFERROR(D24/D11,"") -> 0.063760168 | O24: =IFERROR(E24/E11,"") -> 0.54360598 | P24: =IFERROR(F24/F11,"") -> 0.54556404 | Q24: =IFERROR(G24/G11,"") -> 0.6250257 | R24: =IFERROR(H24/H11,"") -> 0.14813644 | S24: =IFERROR(I24/I11,"") -> 0.2069223 | T24: =IFERROR(J24/J11,"") -> 0.48742279
A25: DÖNEM SONU NAKİT / Cash at end of period | B25: =B24+B23 -> 1185671.5 | C25: =C24+C23 -> 1714149.1 | D25: =D24+D23 -> 1299460.8 | E25: =E24+E23 -> 95201.655 | F25: =F24+F23 -> 65938.818 | G25: =G24+G23 -> 1079753.9 | H25: =H24+H23 -> 652849.27 | I25: =I24+I23 -> 158918.75 | J25: =J24+J23 -> 66110.01 | L25: =IFERROR(B25/B11,"") -> 0.71958471 | M25: =IFERROR(C25/C11,"") -> 0.87705502 | N25: =IFERROR(D25/D11,"") -> 0.87029828 | O25: =IFERROR(E25/E11,"") -> 0.03319713 | P25: =IFERROR(F25/F11,"") -> 0.033316705 | Q25: =IFERROR(G25/G11,"") -> 1.5689333 | R25: =IFERROR(H25/H11,"") -> 0.60855479 | S25: =IFERROR(I25/I11,"") -> 0.49741081 | T25: =IFERROR(J25/J11,"") -> 0.24289401
A29: NOT: B/C/D sütunlarındaki küçük farklar PDF'deki Nakit akışı ile Bilanço'daki Nakit kapsamı arasındaki tanım farkından kaynaklanmaktadır (kısa vadeli mevduat ve benzeri kalemler). | L29: YATAY ANALİZ (Aynı SAG YoY %)
K30: KALEM | L30: 2025/2024(SAG) | M30: 2024/2023(SAG) | N30: 2023/2022(SAG) | O30: 2022/2021(Nom) | P30: 2021/2020(Nom)
K31: İŞLETME FAALİYETLERİNDEN NAKİT AKIŞI | L31: =IFERROR((B11-C11)/ABS(C11),"-") -> -0.15693569 | M31: =IFERROR((D11-E11)/ABS(E11),"-") -> -0.47934375 | N31: =IFERROR((F11-G11)/ABS(G11),"-") -> 1.8758009 | O31: =IFERROR((H11-I11)/ABS(I11),"-") -> 2.3577882 | P31: =IFERROR((I11-J11)/ABS(J11),"-") -> 0.17384165
K32: CAPEX (Sabit Sermaye Yatırımları) | L32: =IFERROR((B13-C13)/ABS(C13),"-") -> 0.38508093 | M32: =IFERROR((D13-E13)/ABS(E13),"-") -> -0.055985695 | N32: =IFERROR((F13-G13)/ABS(G13),"-") -> -10.082844 | O32: =IFERROR((H13-I13)/ABS(I13),"-") -> -0.68178158 | P32: =IFERROR((I13-J13)/ABS(J13),"-") -> 0.80299819
K33: YATIRIM FAALİYETLERİNDEN NAKİT AKIŞI | L33: =IFERROR((B15-C15)/ABS(C15),"-") -> -0.79986392 | M33: =IFERROR((D15-E15)/ABS(E15),"-") -> 0.67972954 | N33: =IFERROR((F15-G15)/ABS(G15),"-") -> -3.2155802 | O33: =IFERROR((H15-I15)/ABS(I15),"-") -> -2.0867601 | P33: =IFERROR((I15-J15)/ABS(J15),"-") -> 0.8038422
K34: Borçlanmalar (net) | L34: =IFERROR((B17-C17)/ABS(C17),"-") -> -0.72426584 | M34: =IFERROR((D17-E17)/ABS(E17),"-") -> 10.463953 | N34: =IFERROR((F17-G17)/ABS(G17),"-") -> 0.77925939 | O34: =IFERROR((H17-I17)/ABS(I17),"-") -> -3.5771871 | P34: =IFERROR((I17-J17)/ABS(J17),"-") -> -1.6752392
K35: Ödenen Temettüler | L35: =IFERROR((B18-C18)/ABS(C18),"-") -> 0.42567119 | M35: =IFERROR((D18-E18)/ABS(E18),"-") -> 0.302473 | N35: =IFERROR((F18-G18)/ABS(G18),"-") -> -0.59619377 | O35: =IFERROR((H18-I18)/ABS(I18),"-") -> -0.5 | P35: =IFERROR((I18-J18)/ABS(J18),"-") -> -9
K36: FİNANSMAN FAALİYETLERİNDEN NAKİT AKIŞI | L36: =IFERROR((B20-C20)/ABS(C20),"-") -> -1.1028487 | M36: =IFERROR((D20-E20)/ABS(E20),"-") -> 1.754277 | N36: =IFERROR((F20-G20)/ABS(G20),"-") -> 0.27548064 | O36: =IFERROR((H20-I20)/ABS(I20),"-") -> -1.3695152 | P36: =IFERROR((I20-J20)/ABS(J20),"-") -> -3.9525327
K37: NAKİT NET ARTIŞ/(AZALIŞ) | L37: =IFERROR((B23-C23)/ABS(C23),"-") -> -1.3324726 | M37: =IFERROR((D23-E23)/ABS(E23),"-") -> 1.8227309 | N37: =IFERROR((F23-G23)/ABS(G23),"-") -> -2.5606626 | O37: =IFERROR((H23-I23)/ABS(I23),"-") -> 4.3220257 | P37: =IFERROR((I23-J23)/ABS(J23),"-") -> 2.3944678
K38: Dönem Başı Nakit | L38: =IFERROR((B24-C24)/ABS(C24),"-") -> 12.755928 | M38: =IFERROR((D24-E24)/ABS(E24),"-") -> -0.93893163 | N38: =IFERROR((F24-G24)/ABS(G24),"-") -> 1.5101904 | O38: =IFERROR((H24-I24)/ABS(I24),"-") -> 1.4038531 | P38: =IFERROR((I24-J24)/ABS(J24),"-") -> -0.50167695
K39: DÖNEM SONU NAKİT | L39: =IFERROR((B25-C25)/ABS(C25),"-") -> -0.30830316 | M39: =IFERROR((D25-E25)/ABS(E25),"-") -> 12.649561 | N39: =IFERROR((F25-G25)/ABS(G25),"-") -> -0.93893162 | O39: =IFERROR((H25-I25)/ABS(I25),"-") -> 3.1080694 | P39: =IFERROR((I25-J25)/ABS(J25),"-") -> 1.4038531
A41: NOTLAR / NOTES:
A42: • 9 sütun yapısı: Her SAG dönemi kendi satın alma gücü cinsinden gösterilmektedir (ASTOR/AKSEN/ENJSA ile aynı format).
A43: • TMS29 'Nakit üzerindeki enflasyon etkisi' 2023'ten itibaren; 2022 ve öncesi Nominal TL (TMS29 öncesi dönem).
A44: • BS ve GelirTablosu tüm 9 sütun için denetçi PDF'leriyle tam mutabakatlıdır (Deloitte 2024-2025, PwC 2020-2023).
...

Sheet GWIND_Ratios
A1: GALATA WIND ENERJİ A.Ş. — FİNANSAL ORAN ANALİZİ / FINANCIAL RATIO ANALYSIS (2020–2025)
A2: Oran Adı | B2: Formül / Formula | C2: Sektörel Referans | D2: 2025 | E2: 2024 | F2: 2023 | G2: 2022 | H2: 2021 | I2: 2020
A3: LİKİDİTE ORANLARI / LIQUIDITY RATIOS
A4: Cari Oran (Current Ratio) | B4: Dönen Var. / KV Yükümlülükler | C4: 1.50–2.00x | D4: =IFERROR(GWIND_BS!B10/GWIND_BS!B22,"-") -> 2.4727971 | E4: =IFERROR(GWIND_BS!D10/GWIND_BS!D22,"-") -> 2.0044355 | F4: =IFERROR(GWIND_BS!F10/GWIND_BS!F22,"-") -> 0.83574765 | G4: =IFERROR(GWIND_BS!H10/GWIND_BS!H22,"-") -> 8.4641167 | H4: =IFERROR(GWIND_BS!I10/GWIND_BS!I22,"-") -> 1.350789 | I4: =IFERROR(GWIND_BS!J10/GWIND_BS!J22,"-") -> 0.56693727
A5: Asit-Test Oranı (Quick Ratio) | B5: (Dönen Var. - Stoklar) / KV Y. | C5: 0.80–1.50x | D5: =IFERROR((GWIND_BS!B10-GWIND_BS!B8)/GWIND_BS!B22,"-") -> 2.467818 | E5: =IFERROR((GWIND_BS!D10-GWIND_BS!D8)/GWIND_BS!D22,"-") -> 1.995648 | F5: =IFERROR((GWIND_BS!F10-GWIND_BS!F8)/GWIND_BS!F22,"-") -> 0.82317281 | G5: =IFERROR((GWIND_BS!H10-GWIND_BS!H8)/GWIND_BS!H22,"-") -> 8.4564876 | H5: =IFERROR((GWIND_BS!I10-GWIND_BS!I8)/GWIND_BS!I22,"-") -> 1.3478901 | I5: =IFERROR((GWIND_BS!J10-GWIND_BS!J8)/GWIND_BS!J22,"-") -> 0.56143311
A6: Nakit Oranı (Cash Ratio) | B6: (Nakit + Fin.Yatırım KV) / KV Y. | C6: > 0.20x | D6: =IFERROR((GWIND_BS!B5+GWIND_BS!B6)/GWIND_BS!B22,"-") -> 2.0786886 | E6: =IFERROR((GWIND_BS!D5+GWIND_BS!D6)/GWIND_BS!D22,"-") -> 1.6338538 | F6: =IFERROR((GWIND_BS!F5+GWIND_BS!F6)/GWIND_BS!F22,"-") -> 0.39505316 | G6: =IFERROR((GWIND_BS!H5+GWIND_BS!H6)/GWIND_BS!H22,"-") -> 6.8526787 | H6: =IFERROR((GWIND_BS!I5+GWIND_BS!I6)/GWIND_BS!I22,"-") -> 0.55171223 | I6: =IFERROR((GWIND_BS!J5+GWIND_BS!J6)/GWIND_BS!J22,"-") -> 0.21859834
A7: BORÇLULUK / FİNANSAL YAPI ORANLARI / LEVERAGE & SOLVENCY
A8: Kaldıraç Oranı (Debt-to-Assets) | B8: Toplam Yüküm. / Toplam Aktifler | C8: %40–%60 | D8: =IFERROR(GWIND_BS!B27/GWIND_BS!B16,"-") -> 0.30530175 | E8: =IFERROR(GWIND_BS!D27/GWIND_BS!D16,"-") -> 0.29392334 | F8: =IFERROR(GWIND_BS!F27/GWIND_BS!F16,"-") -> 0.23218897 | G8: =IFERROR(GWIND_BS!H27/GWIND_BS!H16,"-") -> 0.23359177 | H8: =IFERROR(GWIND_BS!I27/GWIND_BS!I16,"-") -> 0.43556544 | I8: =IFERROR(GWIND_BS!J27/GWIND_BS!J16,"-") -> 0.42784975
A9: Borç / Özkaynak (D/E) | B9: Toplam Yüküm. / Özkaynak | C9: 0.50–1.50x | D9: =IFERROR(GWIND_BS!B27/GWIND_BS!B33,"-") -> 0.4394739 | E9: =IFERROR(GWIND_BS!D27/GWIND_BS!D33,"-") -> 0.41627681 | F9: =IFERROR(GWIND_BS!F27/GWIND_BS!F33,"-") -> 0.3024038 | G9: =IFERROR(GWIND_BS!H27/GWIND_BS!H33,"-") -> 0.30478766 | H9: =IFERROR(GWIND_BS!I27/GWIND_BS!I33,"-") -> 0.77168455 | I9: =IFERROR(GWIND_BS!J27/GWIND_BS!J33,"-") -> 0.74779264
A10: Fin. Borç / Özkaynak (Net Debt Ratio) | B10: (KV+UV Fin.Borç) / Özkaynak | C10: 0.30–1.00x | D10: =IFERROR((GWIND_BS!B19+GWIND_BS!B24)/GWIND_BS!B33,"-") -> 0.23587279 | E10: =IFERROR((GWIND_BS!D19+GWIND_BS!D24)/GWIND_BS!D33,"-") -> 0.21914689 | F10: =IFERROR((GWIND_BS!F19+GWIND_BS!F24)/GWIND_BS!F33,"-") -> 0.10999133 | G10: =IFERROR((GWIND_BS!H19+GWIND_BS!H24)/GWIND_BS!H33,"-") -> 0.27860062 | H10: =IFERROR((GWIND_BS!I19+GWIND_BS!I24)/GWIND_BS!I33,"-") -> 0.64932679 | I10: =IFERROR((GWIND_BS!J19+GWIND_BS!J24)/GWIND_BS!J33,"-") -> 0.44926148
A11: Net Borç / FAVÖK | B11: (Fin.Borç - Nakit - Fin.Yat.) / FAVÖK | C11: < 2.00x | D11: =IFERROR((GWIND_BS!B19+GWIND_BS!B24-GWIND_BS!B5-GWIND_BS!B6)/GWIND_PLS!B13,"-") -> 0.59609549 | E11: =IFERROR((GWIND_BS!D19+GWIND_BS!D24-GWIND_BS!D5-GWIND_BS!D6)/GWIND_PLS!D13,"-") -> 0.5571529 | F11: =IFERROR((GWIND_BS!F19+GWIND_BS!F24-GWIND_BS!F5-GWIND_BS!F6)/GWIND_PLS!F13,"-") -> 0.33274816 | G11: =IFERROR((GWIND_BS!H19+GWIND_BS!H24-GWIND_BS!H5-GWIND_BS!H6)/GWIND_PLS!H13,"-") -> -0.17825263 | H11: =IFERROR((GWIND_BS!I19+GWIND_BS!I24-GWIND_BS!I5-GWIND_BS!I6)/GWIND_PLS!I13,"-") -> 1.0435594 | I11: =IFERROR((GWIND_BS!J19+GWIND_BS!J24-GWIND_BS!J5-GWIND_BS!J6)/GWIND_PLS!J13,"-") -> 1.1346777
A12: Faiz Karşılama (Interest Coverage) | B12: EBIT / |Finansman Giderleri| | C12: > 4.00x | D12: =IFERROR(GWIND_PLS!B11/ABS(GWIND_PLS!B14),"-") -> 2.9953345 | E12: =IFERROR(GWIND_PLS!D11/ABS(GWIND_PLS!D14),"-") -> 5.6853892 | F12: =IFERROR(GWIND_PLS!F11/ABS(GWIND_PLS!F14),"-") -> 4.1260835 | G12: =IFERROR(GWIND_PLS!H11/ABS(GWIND_PLS!H14),"-") -> 6.4632921 | H12: =IFERROR(GWIND_PLS!I11/ABS(GWIND_PLS!I14),"-") -> 1.9395522 | I12: =IFERROR(GWIND_PLS!J11/ABS(GWIND_PLS!J14),"-") -> 3.6287574
A13: Özkaynak Çarpanı (Equity Multiplier) | B13: Toplam Aktifler / Özkaynak | C13: 1.50–2.50x | D13: =IFERROR(GWIND_BS!B16/GWIND_BS!B33,"-") -> 1.4394739 | E13: =IFERROR(GWIND_BS!D16/GWIND_BS!D33,"-") -> 1.4162768 | F13: =IFERROR(GWIND_BS!F16/GWIND_BS!F33,"-") -> 1.3024038 | G13: =IFERROR(GWIND_BS!H16/GWIND_BS!H33,"-") -> 1.3047877 | H13: =IFERROR(GWIND_BS!I16/GWIND_BS!I33,"-") -> 1.7716846 | I13: =IFERROR(GWIND_BS!J16/GWIND_BS!J33,"-") -> 1.7477926
A14: KARLILIK ORANLARI / PROFITABILITY RATIOS
A15: Brüt Kar Marjı (Gross Margin) | B15: Brüt Kar / Hasılat | C15: %50–%70 (enerji üret.) | D15: =IFERROR(GWIND_PLS!B6/GWIND_PLS!B4,"-") -> 0.45802346 | E15: =IFERROR(GWIND_PLS!D6/GWIND_PLS!D4,"-") -> 0.52498155 | F15: =IFERROR(GWIND_PLS!F6/GWIND_PLS!F4,"-") -> 0.59479669 | G15: =IFERROR(GWIND_PLS!H6/GWIND_PLS!H4,"-") -> 0.82020202 | H15: =IFERROR(GWIND_PLS!I6/GWIND_PLS!I4,"-") -> 0.73091507 | I15: =IFERROR(GWIND_PLS!J6/GWIND_PLS!J4,"-") -> 0.73536653
A16: FAVÖK Marjı (EBITDA Margin) | B16: FAVÖK / Hasılat | C16: %60–%90 (enerji üret.) | D16: =IFERROR(GWIND_PLS!B13/GWIND_PLS!B4,"-") -> 0.85131405 | E16: =IFERROR(GWIND_PLS!D13/GWIND_PLS!D4,"-") -> 0.73871873 | F16: =IFERROR(GWIND_PLS!F13/GWIND_PLS!F4,"-") -> 1.0010718 | G16: =IFERROR(GWIND_PLS!H13/GWIND_PLS!H4,"-") -> 0.98640529 | H16: =IFERROR(GWIND_PLS!I13/GWIND_PLS!I4,"-") -> 0.86722573 | I16: =IFERROR(GWIND_PLS!J13/GWIND_PLS!J4,"-") -> 0.92139046
A17: EBIT Marjı (Operating Margin) | B17: EBIT / Hasılat | C17: %50–%80 (enerji üret.) | D17: =IFERROR(GWIND_PLS!B11/GWIND_PLS!B4,"-") -> 0.52347161 | E17: =IFERROR(GWIND_PLS!D11/GWIND_PLS!D4,"-") -> 0.47611319 | F17: =IFERROR(GWIND_PLS!F11/GWIND_PLS!F4,"-") -> 0.79214203 | G17: =IFERROR(GWIND_PLS!H11/GWIND_PLS!H4,"-") -> 0.93201364 | H17: =IFERROR(GWIND_PLS!I11/GWIND_PLS!I4,"-") -> 0.75030813 | I17: =IFERROR(GWIND_PLS!J11/GWIND_PLS!J4,"-") -> 0.81833413
A18: Net Kar Marjı (Net Margin) | B18: Net Kar / Hasılat | C18: %20–%50 | D18: =IFERROR(GWIND_PLS!B20/GWIND_PLS!B4,"-") -> 0.28759055 | E18: =IFERROR(GWIND_PLS!D20/GWIND_PLS!D4,"-") -> 0.35290564 | F18: =IFERROR(GWIND_PLS!F20/GWIND_PLS!F4,"-") -> 0.33541513 | G18: =IFERROR(GWIND_PLS!H20/GWIND_PLS!H4,"-") -> 0.87928974 | H18: =IFERROR(GWIND_PLS!I20/GWIND_PLS!I4,"-") -> 0.31637272 | I18: =IFERROR(GWIND_PLS!J20/GWIND_PLS!J4,"-") -> 0.46645475
A19: ROA (Aktif Karlılığı) | B19: Net Kar / Toplam Aktifler (YE) | C19: %5–%15 | D19: =IFERROR(GWIND_PLS!B20/GWIND_BS!B16,"-") -> 0.041567606 | E19: =IFERROR(GWIND_PLS!D20/GWIND_BS!D16,"-") -> 0.056342832 | F19: =IFERROR(GWIND_PLS!F20/GWIND_BS!F16,"-") -> 0.068076323 | G19: =IFERROR(GWIND_PLS!H20/GWIND_BS!H16,"-") -> 0.42327828 | H19: =IFERROR(GWIND_PLS!I20/GWIND_BS!I16,"-") -> 0.096692806 | I19: =IFERROR(GWIND_PLS!J20/GWIND_BS!J16,"-") -> 0.096479541
A20: ROE (Özkaynak Karlılığı) | B20: Net Kar / Özkaynak (YE) | C20: %15–%35 | D20: =IFERROR(GWIND_PLS!B20/GWIND_BS!B33,"-") -> 0.059835484 | E20: =IFERROR(GWIND_PLS!D20/GWIND_BS!D33,"-") -> 0.079797047 | F20: =IFERROR(GWIND_PLS!F20/GWIND_BS!F33,"-") -> 0.088662861 | G20: =IFERROR(GWIND_PLS!H20/GWIND_BS!H33,"-") -> 0.55228828 | H20: =IFERROR(GWIND_PLS!I20/GWIND_BS!I33,"-") -> 0.17130915 | I20: =IFERROR(GWIND_PLS!J20/GWIND_BS!J33,"-") -> 0.16862623
A21: Karlılık Kaldıracı (ROE / ROA) | B21: ROE / ROA | C21: — | D21: =IFERROR((GWIND_PLS!B20/GWIND_BS!B33)/(GWIND_PLS!B20/GWIND_BS!B16),"-") -> 1.4394739 | E21: =IFERROR((GWIND_PLS!D20/GWIND_BS!D33)/(GWIND_PLS!D20/GWIND_BS!D16),"-") -> 1.4162768 | F21: =IFERROR((GWIND_PLS!F20/GWIND_BS!F33)/(GWIND_PLS!F20/GWIND_BS!F16),"-") -> 1.3024038 | G21: =IFERROR((GWIND_PLS!H20/GWIND_BS!H33)/(GWIND_PLS!H20/GWIND_BS!H16),"-") -> 1.3047877 | H21: =IFERROR((GWIND_PLS!I20/GWIND_BS!I33)/(GWIND_PLS!I20/GWIND_BS!I16),"-") -> 1.7716846 | I21: =IFERROR((GWIND_PLS!J20/GWIND_BS!J33)/(GWIND_PLS!J20/GWIND_BS!J16),"-") -> 1.7477926
A22: FAALİYET VERİMLİLİĞİ / OPERATING EFFICIENCY
A23: Aktif Devir Hızı (Asset Turnover) | B23: Hasılat / Toplam Aktifler | C23: 0.15–0.40x | D23: =IFERROR(GWIND_PLS!B4/GWIND_BS!B16,"-") -> 0.14453746 | E23: =IFERROR(GWIND_PLS!D4/GWIND_BS!D16,"-") -> 0.1596541 | F23: =IFERROR(GWIND_PLS!F4/GWIND_BS!F16,"-") -> 0.20296139 | G23: =IFERROR(GWIND_PLS!H4/GWIND_BS!H16,"-") -> 0.48138658 | H23: =IFERROR(GWIND_PLS!I4/GWIND_BS!I16,"-") -> 0.3056294 | I23: =IFERROR(GWIND_PLS!J4/GWIND_BS!J16,"-") -> 0.2068358
A24: Tic. Alacak Devir Hızı (T/R Turnover) | B24: Hasılat / Ticari Alacaklar | C24: 5–20x | D24: =IFERROR(GWIND_PLS!B4/GWIND_BS!B7,"-") -> 10.335926 | E24: =IFERROR(GWIND_PLS!D4/GWIND_BS!D7,"-") -> 10.748352 | F24: =IFERROR(GWIND_PLS!F4/GWIND_BS!F7,"-") -> 13.441193 | G24: =IFERROR(GWIND_PLS!H4/GWIND_BS!H7,"-") -> 14.112614 | H24: =IFERROR(GWIND_PLS!I4/GWIND_BS!I7,"-") -> 6.4066897 | I24: =IFERROR(GWIND_PLS!J4/GWIND_BS!J7,"-") -> 9.6296273
A25: Ort. Tahsilat Süresi (DSO, gün) | B25: 365 / Alacak Devir Hızı | C25: 20–80 gün | D25: =IFERROR(365/(GWIND_PLS!B4/GWIND_BS!B7),"-") -> 35.313719 | E25: =IFERROR(365/(GWIND_PLS!D4/GWIND_BS!D7),"-") -> 33.958695 | F25: =IFERROR(365/(GWIND_PLS!F4/GWIND_BS!F7),"-") -> 27.155327 | G25: =IFERROR(365/(GWIND_PLS!H4/GWIND_BS!H7),"-") -> 25.863387 | H25: =IFERROR(365/(GWIND_PLS!I4/GWIND_BS!I7),"-") -> 56.9717 | I25: =IFERROR(365/(GWIND_PLS!J4/GWIND_BS!J7),"-") -> 37.903855
A26: Stok Devir Hızı (Inventory Turnover) | B26: SMM / Stoklar (YE) | C26: 50–300x | D26: =IFERROR(ABS(GWIND_PLS!B5)/GWIND_BS!B8,"-") -> 361.32217 | E26: =IFERROR(ABS(GWIND_PLS!D5)/GWIND_BS!D8,"-") -> 158.3918 | F26: =IFERROR(ABS(GWIND_PLS!F5)/GWIND_BS!F8,"-") -> 153.37855 | G26: =IFERROR(ABS(GWIND_PLS!H5)/GWIND_BS!H8,"-") -> 260.74311 | H26: =IFERROR(ABS(GWIND_PLS!I5)/GWIND_BS!I8,"-") -> 174.08733 | I26: =IFERROR(ABS(GWIND_PLS!J5)/GWIND_BS!J8,"-") -> 53.277407
A27: Ort. Stok Süresi (Days Inventory, gün) | B27: 365 / Stok Devir Hızı | C27: 1–10 gün | D27: =IFERROR(365/(ABS(GWIND_PLS!B5)/GWIND_BS!B8),"-") -> 1.0101788 | E27: =IFERROR(365/(ABS(GWIND_PLS!D5)/GWIND_BS!D8),"-") -> 2.3044122 | F27: =IFERROR(365/(ABS(GWIND_PLS!F5)/GWIND_BS!F8),"-") -> 2.379733 | G27: =IFERROR(365/(ABS(GWIND_PLS!H5)/GWIND_BS!H8),"-") -> 1.3998453 | H27: =IFERROR(365/(ABS(GWIND_PLS!I5)/GWIND_BS!I8),"-") -> 2.0966489 | I27: =IFERROR(365/(ABS(GWIND_PLS!J5)/GWIND_BS!J8),"-") -> 6.850934
A28: Tic. Borç Devir Hızı (Trade Pay. Turnover) | B28: Hasılat / Ticari Borçlar | C28: 10–50x | D28: =IFERROR(GWIND_PLS!B4/GWIND_BS!B20,"-") -> 48.165011 | E28: =IFERROR(GWIND_PLS!D4/GWIND_BS!D20,"-") -> 17.080619 | F28: =IFERROR(GWIND_PLS!F4/GWIND_BS!F20,"-") -> 26.430996 | G28: =IFERROR(GWIND_PLS!H4/GWIND_BS!H20,"-") -> 67.961822 | H28: =IFERROR(GWIND_PLS!I4/GWIND_BS!I20,"-") -> 60.878839 | I28: =IFERROR(GWIND_PLS!J4/GWIND_BS!J20,"-") -> 47.543733
A29: NAKİT AKIŞ ORANLARI / CASH FLOW RATIOS
A30: İşletme Nakdi / Net Kar | B30: OCF / Net Dönem Karı | C30: > 0.80x | D30: =IFERROR(GWIND_CFS!B11/GWIND_PLS!B20,"-") -> 1.948974 | E30: =IFERROR(GWIND_CFS!D11/GWIND_PLS!D20,"-") -> 1.7894333 | F30: =IFERROR(GWIND_CFS!F11/GWIND_PLS!F20,"-") -> 3.1740181 | G30: =IFERROR(GWIND_CFS!H11/GWIND_PLS!H20,"-") -> 1.0276165 | H30: =IFERROR(GWIND_CFS!I11/GWIND_PLS!I20,"-") -> 1.8693266 | I30: =IFERROR(GWIND_CFS!J11/GWIND_PLS!J20,"-") -> 1.7407418
A31: FAVÖK / Faiz Gideri | B31: FAVÖK / |Finansman Gid.| | C31: > 3.00x | D31: =IFERROR(GWIND_PLS!B13/ABS(GWIND_PLS!B14),"-") -> 4.8712677 | E31: =IFERROR(GWIND_PLS!D13/ABS(GWIND_PLS!D14),"-") -> 8.821229 | F31: =IFERROR(GWIND_PLS!F13/ABS(GWIND_PLS!F14),"-") -> 5.2143503 | G31: =IFERROR(GWIND_PLS!H13/ABS(GWIND_PLS!H14),"-") -> 6.8404852 | H31: =IFERROR(GWIND_PLS!I13/ABS(GWIND_PLS!I14),"-") -> 2.241785 | I31: =IFERROR(GWIND_PLS!J13/ABS(GWIND_PLS!J14),"-") -> 4.0857424
A32: Serbest Nakit Akışı / Hasılat | B32: (OCF + CAPEX) / Hasılat | C32: > %5 | D32: =IFERROR((GWIND_CFS!B11+GWIND_CFS!B13)/GWIND_PLS!B4,"-") -> 0.011574742 | E32: =IFERROR((GWIND_CFS!D11+GWIND_CFS!D13)/GWIND_PLS!D4,"-") -> -0.21644269 | F32: =IFERROR((GWIND_CFS!F11+GWIND_CFS!F13)/GWIND_PLS!F4,"-") -> 0.34809709 | G32: =IFERROR((GWIND_CFS!H11+GWIND_CFS!H13)/GWIND_PLS!H4,"-") -> 0.78506904 | H32: =IFERROR((GWIND_CFS!I11+GWIND_CFS!I13)/GWIND_PLS!I4,"-") -> 0.43654498 | I32: =IFERROR((GWIND_CFS!J11+GWIND_CFS!J13)/GWIND_PLS!J4,"-") -> -0.4549023
A33: HİSSE ANALİZİ / EQUITY METRICS
A34: Hisse Adedi (mn) (Shares Outstanding) | B34: Ödenmiş Sermaye / 1000 (mn pay) | C34: — | D34: =IFERROR(GWIND_BS!B29/1000,"-") -> 540 | E34: =IFERROR(GWIND_BS!D29/1000,"-") -> 540 | F34: =IFERROR(GWIND_BS!F29/1000,"-") -> 540 | G34: =IFERROR(GWIND_BS!H29/1000,"-") -> 534.79146 | H34: =IFERROR(GWIND_BS!I29/1000,"-") -> 534.79146 | I34: =IFERROR(GWIND_BS!J29/1000,"-") -> 534.79146
A35: Hisse Başına Kazanç - TL (EPS) | B35: Net Kar / Hisse Adedi (BinTL/BinTL = TL/pay) | C35: — | D35: =IFERROR(GWIND_PLS!B20/GWIND_BS!B29,"-") -> 1.5656066 | E35: =IFERROR(GWIND_PLS!D20/GWIND_BS!D29,"-") -> 1.5452038 | F35: =IFERROR(GWIND_PLS!F20/GWIND_BS!F29,"-") -> 1.154718 | G35: =IFERROR(GWIND_PLS!H20/GWIND_BS!H29,"-") -> 1.9520804 | H35: =IFERROR(GWIND_PLS!I20/GWIND_BS!I29,"-") -> 0.31958786 | I35: =IFERROR(GWIND_PLS!J20/GWIND_BS!J29,"-") -> 0.29236918
A36: Hisse Başına Defter Değeri - TL (BVPS) | B36: Özkaynak / Hisse Adedi | C36: — | D36: =IFERROR(GWIND_BS!B33/GWIND_BS!B29,"-") -> 26.165186 | E36: =IFERROR(GWIND_BS!D33/GWIND_BS!D29,"-") -> 19.364173 | F36: =IFERROR(GWIND_BS!F33/GWIND_BS!F29,"-") -> 13.023695 | G36: =IFERROR(GWIND_BS!H33/GWIND_BS!H29,"-") -> 3.5345317 | H36: =IFERROR(GWIND_BS!I33/GWIND_BS!I29,"-") -> 1.8655621 | I36: =IFERROR(GWIND_BS!J33/GWIND_BS!J29,"-") -> 1.7338298
A37: Hisse Başına Temettü - TL (DPS) | B37: |Ödenen Temettü| / Hisse Adedi | C37: — | D37: =IFERROR(ABS(GWIND_CFS!B18)/GWIND_BS!B29,"-") -> 0.73983224 | E37: =IFERROR(ABS(GWIND_CFS!D18)/GWIND_BS!D29,"-") -> 0.98414358 | F37: =IFERROR(ABS(GWIND_CFS!F18)/GWIND_BS!F29,"-") -> 0.97722394 | G37: =IFERROR(ABS(GWIND_CFS!H18)/GWIND_BS!H29,"-") -> 0.28048316 | H37: =IFERROR(ABS(GWIND_CFS!I18)/GWIND_BS!I29,"-") -> 0.18698878 | I37: =IFERROR(ABS(GWIND_CFS!J18)/GWIND_BS!J29,"-") -> 0.018698878
A38: DEĞERLEME ÇARPANLARI / VALUATION MULTIPLES
A39: Dönem Sonu Hisse Fiyatı - TL (Year-end share price) | B39: BIST son işlem günü kapanışı (Year-end close) | C39: N/A 2020 (halka arz öncesi) | D39: 26.46 | E39: 28.44 | F39: 26.18 | G39: 16.67 | H39: 6.73 | I39: IPO öncesi / Pre-IPO
A40: Piyasa Değeri - Bin TL (Market Cap) | B40: Hisse Fiyatı × Hisse Adedi (BinTL) | C40: — | D40: =IFERROR(D39*GWIND_BS!B29,"-") -> 14288400 | E40: =IFERROR(E39*GWIND_BS!D29,"-") -> 15357600 | F40: =IFERROR(F39*GWIND_BS!F29,"-") -> 14137200 | G40: =IFERROR(G39*GWIND_BS!H29,"-") -> 8914973.6 | H40: =IFERROR(H39*GWIND_BS!I29,"-") -> 3599146.5 | I40: N/A
...

Sheet ASTOR_BS
A1: ASTOR ENERJİ A.Ş. — KONSOLİDE BİLANÇO / CONSOLIDATED BALANCE SHEET | L1: DİKEY ANALİZ (% TOPLAM AKTİF)
A2: KALEM (BİN TL) | B2: 31.12.2025 (2025 SAG) | C2: 31.12.2024 (2025 SAG) | D2: 31.12.2024 (2024 SAG) | E2: 31.12.2023 (2024 SAG) | F2: 31.12.2023 (2023 SAG) | G2: 31.12.2022 (2023 SAG) | H2: 31.12.2022 (Nominal) | I2: 31.12.2021 (Nominal) | J2: 31.12.2020 (Nominal) | L2: 31.12.2025 (2025 SAG) | M2: 31.12.2024 (2025 SAG) | N2: 31.12.2024 (2024 SAG) | O2: 31.12.2023 (2024 SAG) | P2: 31.12.2023 (2023 SAG) | Q2: 31.12.2022 (2023 SAG) | R2: 31.12.2022 (Nominal) | S2: 31.12.2021 (Nominal) | T2: 31.12.2020 (Nominal)
A3: VARLIKLAR
A4: DÖNEN VARLIKLAR
